[2022-11-26 06:56:59,729] {taskinstance.py:1032} INFO - Dependencies all met for <TaskInstance: LocalIngestationDag.ingestation manual__2022-11-26T06:56:48.773933+00:00 [queued]>
[2022-11-26 06:56:59,774] {taskinstance.py:1032} INFO - Dependencies all met for <TaskInstance: LocalIngestationDag.ingestation manual__2022-11-26T06:56:48.773933+00:00 [queued]>
[2022-11-26 06:56:59,776] {taskinstance.py:1238} INFO - 
--------------------------------------------------------------------------------
[2022-11-26 06:56:59,777] {taskinstance.py:1239} INFO - Starting attempt 1 of 1
[2022-11-26 06:56:59,778] {taskinstance.py:1240} INFO - 
--------------------------------------------------------------------------------
[2022-11-26 06:56:59,824] {taskinstance.py:1259} INFO - Executing <Task(PythonOperator): ingestation> on 2022-11-26 06:56:48.773933+00:00
[2022-11-26 06:56:59,834] {standard_task_runner.py:52} INFO - Started process 692 to run task
[2022-11-26 06:56:59,845] {standard_task_runner.py:76} INFO - Running: ['***', 'tasks', 'run', 'LocalIngestationDag', 'ingestation', 'manual__2022-11-26T06:56:48.773933+00:00', '--job-id', '45', '--raw', '--subdir', 'DAGS_FOLDER/data_ingestation.py', '--cfg-path', '/tmp/tmpll9r359v', '--error-file', '/tmp/tmpouois7g1']
[2022-11-26 06:56:59,848] {standard_task_runner.py:77} INFO - Job 45: Subtask ingestation
[2022-11-26 06:57:00,036] {logging_mixin.py:109} INFO - Running <TaskInstance: LocalIngestationDag.ingestation manual__2022-11-26T06:56:48.773933+00:00 [running]> on host 951f10ff76c7
[2022-11-26 06:57:00,270] {logging_mixin.py:109} WARNING - /home/***/.local/lib/python3.7/site-packages/***/utils/context.py:152 AirflowContextDeprecationWarning: Accessing 'execution_date' from the template is deprecated and will be removed in a future version. Please use 'data_interval_start' or 'logical_date' instead.
[2022-11-26 06:57:00,380] {taskinstance.py:1426} INFO - Exporting the following env vars:
AIRFLOW_CTX_DAG_OWNER=***
AIRFLOW_CTX_DAG_ID=LocalIngestationDag
AIRFLOW_CTX_TASK_ID=ingestation
AIRFLOW_CTX_EXECUTION_DATE=2022-11-26T06:56:48.773933+00:00
AIRFLOW_CTX_DAG_RUN_ID=manual__2022-11-26T06:56:48.773933+00:00
[2022-11-26 06:57:00,389] {logging_mixin.py:109} INFO - connection established successfully, inserting data...
[2022-11-26 06:57:00,763] {taskinstance.py:1700} ERROR - Task failed with exception
Traceback (most recent call last):
  File "/home/airflow/.local/lib/python3.7/site-packages/airflow/models/taskinstance.py", line 1329, in _run_raw_task
    self._execute_task_with_callbacks(context)
  File "/home/airflow/.local/lib/python3.7/site-packages/airflow/models/taskinstance.py", line 1455, in _execute_task_with_callbacks
    result = self._execute_task(context, self.task)
  File "/home/airflow/.local/lib/python3.7/site-packages/airflow/models/taskinstance.py", line 1511, in _execute_task
    result = execute_callable(context=context)
  File "/home/airflow/.local/lib/python3.7/site-packages/airflow/operators/python.py", line 174, in execute
    return_value = self.execute_callable()
  File "/home/airflow/.local/lib/python3.7/site-packages/airflow/operators/python.py", line 185, in execute_callable
    return self.python_callable(*self.op_args, **self.op_kwargs)
  File "/opt/airflow/dags/ingest_script.py", line 13, in ingest_callable
    df = pd.read_parquet(file)
  File "/home/airflow/.local/lib/python3.7/site-packages/pandas/io/parquet.py", line 500, in read_parquet
    **kwargs,
  File "/home/airflow/.local/lib/python3.7/site-packages/pandas/io/parquet.py", line 240, in read
    path_or_handle, columns=columns, **kwargs
  File "/home/airflow/.local/lib/python3.7/site-packages/pyarrow/parquet.py", line 1869, in read_table
    coerce_int96_timestamp_unit=coerce_int96_timestamp_unit
  File "/home/airflow/.local/lib/python3.7/site-packages/pyarrow/parquet.py", line 1679, in __init__
    [fragment], schema=fragment.physical_schema,
  File "pyarrow/_dataset.pyx", line 952, in pyarrow._dataset.Fragment.physical_schema.__get__
  File "pyarrow/error.pxi", line 143, in pyarrow.lib.pyarrow_internal_check_status
  File "pyarrow/error.pxi", line 99, in pyarrow.lib.check_status
pyarrow.lib.ArrowInvalid: Could not open Parquet input source '<Buffer>': Parquet magic bytes not found in footer. Either the file is corrupted or this is not a parquet file.
[2022-11-26 06:57:00,823] {taskinstance.py:1277} INFO - Marking task as FAILED. dag_id=LocalIngestationDag, task_id=ingestation, execution_date=20221126T065648, start_date=20221126T065659, end_date=20221126T065700
[2022-11-26 06:57:00,883] {standard_task_runner.py:92} ERROR - Failed to execute job 45 for task ingestation
Traceback (most recent call last):
  File "/home/airflow/.local/lib/python3.7/site-packages/airflow/task/task_runner/standard_task_runner.py", line 85, in _start_by_fork
    args.func(args, dag=self.dag)
  File "/home/airflow/.local/lib/python3.7/site-packages/airflow/cli/cli_parser.py", line 48, in command
    return func(*args, **kwargs)
  File "/home/airflow/.local/lib/python3.7/site-packages/airflow/utils/cli.py", line 92, in wrapper
    return f(*args, **kwargs)
  File "/home/airflow/.local/lib/python3.7/site-packages/airflow/cli/commands/task_command.py", line 298, in task_run
    _run_task_by_selected_method(args, dag, ti)
  File "/home/airflow/.local/lib/python3.7/site-packages/airflow/cli/commands/task_command.py", line 107, in _run_task_by_selected_method
    _run_raw_task(args, ti)
  File "/home/airflow/.local/lib/python3.7/site-packages/airflow/cli/commands/task_command.py", line 184, in _run_raw_task
    error_file=args.error_file,
  File "/home/airflow/.local/lib/python3.7/site-packages/airflow/utils/session.py", line 70, in wrapper
    return func(*args, session=session, **kwargs)
  File "/home/airflow/.local/lib/python3.7/site-packages/airflow/models/taskinstance.py", line 1329, in _run_raw_task
    self._execute_task_with_callbacks(context)
  File "/home/airflow/.local/lib/python3.7/site-packages/airflow/models/taskinstance.py", line 1455, in _execute_task_with_callbacks
    result = self._execute_task(context, self.task)
  File "/home/airflow/.local/lib/python3.7/site-packages/airflow/models/taskinstance.py", line 1511, in _execute_task
    result = execute_callable(context=context)
  File "/home/airflow/.local/lib/python3.7/site-packages/airflow/operators/python.py", line 174, in execute
    return_value = self.execute_callable()
  File "/home/airflow/.local/lib/python3.7/site-packages/airflow/operators/python.py", line 185, in execute_callable
    return self.python_callable(*self.op_args, **self.op_kwargs)
  File "/opt/airflow/dags/ingest_script.py", line 13, in ingest_callable
    df = pd.read_parquet(file)
  File "/home/airflow/.local/lib/python3.7/site-packages/pandas/io/parquet.py", line 500, in read_parquet
    **kwargs,
  File "/home/airflow/.local/lib/python3.7/site-packages/pandas/io/parquet.py", line 240, in read
    path_or_handle, columns=columns, **kwargs
  File "/home/airflow/.local/lib/python3.7/site-packages/pyarrow/parquet.py", line 1869, in read_table
    coerce_int96_timestamp_unit=coerce_int96_timestamp_unit
  File "/home/airflow/.local/lib/python3.7/site-packages/pyarrow/parquet.py", line 1679, in __init__
    [fragment], schema=fragment.physical_schema,
  File "pyarrow/_dataset.pyx", line 952, in pyarrow._dataset.Fragment.physical_schema.__get__
  File "pyarrow/error.pxi", line 143, in pyarrow.lib.pyarrow_internal_check_status
  File "pyarrow/error.pxi", line 99, in pyarrow.lib.check_status
pyarrow.lib.ArrowInvalid: Could not open Parquet input source '<Buffer>': Parquet magic bytes not found in footer. Either the file is corrupted or this is not a parquet file.
[2022-11-26 06:57:00,928] {local_task_job.py:154} INFO - Task exited with return code 1
[2022-11-26 06:57:01,028] {local_task_job.py:264} INFO - 0 downstream tasks scheduled from follow-on schedule check
