[2022-11-27 03:53:37,215] {taskinstance.py:1032} INFO - Dependencies all met for <TaskInstance: data_ingestation_gcp_dag.local_to_gcp_task scheduled__2019-01-02T06:00:00+00:00 [queued]>
[2022-11-27 03:53:37,274] {taskinstance.py:1032} INFO - Dependencies all met for <TaskInstance: data_ingestation_gcp_dag.local_to_gcp_task scheduled__2019-01-02T06:00:00+00:00 [queued]>
[2022-11-27 03:53:37,275] {taskinstance.py:1238} INFO - 
--------------------------------------------------------------------------------
[2022-11-27 03:53:37,276] {taskinstance.py:1239} INFO - Starting attempt 2 of 2
[2022-11-27 03:53:37,277] {taskinstance.py:1240} INFO - 
--------------------------------------------------------------------------------
[2022-11-27 03:53:37,338] {taskinstance.py:1259} INFO - Executing <Task(PythonOperator): local_to_gcp_task> on 2019-01-02 06:00:00+00:00
[2022-11-27 03:53:37,350] {standard_task_runner.py:52} INFO - Started process 972 to run task
[2022-11-27 03:53:37,361] {standard_task_runner.py:76} INFO - Running: ['***', 'tasks', 'run', 'data_ingestation_gcp_dag', 'local_to_gcp_task', 'scheduled__2019-01-02T06:00:00+00:00', '--job-id', '121', '--raw', '--subdir', 'DAGS_FOLDER/data_ingestation_gcp.py', '--cfg-path', '/tmp/tmpy0kcvfby', '--error-file', '/tmp/tmpub4p3nnx']
[2022-11-27 03:53:37,364] {standard_task_runner.py:77} INFO - Job 121: Subtask local_to_gcp_task
[2022-11-27 03:53:37,529] {logging_mixin.py:109} INFO - Running <TaskInstance: data_ingestation_gcp_dag.local_to_gcp_task scheduled__2019-01-02T06:00:00+00:00 [running]> on host 410f3484ae43
[2022-11-27 03:53:37,710] {logging_mixin.py:109} WARNING - /home/***/.local/lib/python3.7/site-packages/***/utils/context.py:152 AirflowContextDeprecationWarning: Accessing 'execution_date' from the template is deprecated and will be removed in a future version. Please use 'data_interval_start' or 'logical_date' instead.
[2022-11-27 03:53:37,778] {taskinstance.py:1426} INFO - Exporting the following env vars:
AIRFLOW_CTX_DAG_OWNER=***
AIRFLOW_CTX_DAG_ID=data_ingestation_gcp_dag
AIRFLOW_CTX_TASK_ID=local_to_gcp_task
AIRFLOW_CTX_EXECUTION_DATE=2019-01-02T06:00:00+00:00
AIRFLOW_CTX_DAG_RUN_ID=scheduled__2019-01-02T06:00:00+00:00
[2022-11-27 03:53:37,783] {taskinstance.py:1700} ERROR - Task failed with exception
Traceback (most recent call last):
  File "/home/airflow/.local/lib/python3.7/site-packages/airflow/models/taskinstance.py", line 1329, in _run_raw_task
    self._execute_task_with_callbacks(context)
  File "/home/airflow/.local/lib/python3.7/site-packages/airflow/models/taskinstance.py", line 1455, in _execute_task_with_callbacks
    result = self._execute_task(context, self.task)
  File "/home/airflow/.local/lib/python3.7/site-packages/airflow/models/taskinstance.py", line 1511, in _execute_task
    result = execute_callable(context=context)
  File "/home/airflow/.local/lib/python3.7/site-packages/airflow/operators/python.py", line 174, in execute
    return_value = self.execute_callable()
  File "/home/airflow/.local/lib/python3.7/site-packages/airflow/operators/python.py", line 185, in execute_callable
    return self.python_callable(*self.op_args, **self.op_kwargs)
  File "/opt/airflow/dags/data_ingestation_gcp.py", line 39, in upload_to_gcs
    client = storage.Client()
  File "/home/airflow/.local/lib/python3.7/site-packages/google/cloud/storage/client.py", line 128, in __init__
    _http=_http,
  File "/home/airflow/.local/lib/python3.7/site-packages/google/cloud/client.py", line 318, in __init__
    _ClientProjectMixin.__init__(self, project=project, credentials=credentials)
  File "/home/airflow/.local/lib/python3.7/site-packages/google/cloud/client.py", line 266, in __init__
    project = self._determine_default(project)
  File "/home/airflow/.local/lib/python3.7/site-packages/google/cloud/client.py", line 285, in _determine_default
    return _determine_default_project(project)
  File "/home/airflow/.local/lib/python3.7/site-packages/google/cloud/_helpers.py", line 186, in _determine_default_project
    _, project = google.auth.default()
  File "/home/airflow/.local/lib/python3.7/site-packages/google/auth/_default.py", line 459, in default
    credentials, project_id = checker()
  File "/home/airflow/.local/lib/python3.7/site-packages/google/auth/_default.py", line 222, in _get_explicit_environ_credentials
    os.environ[environment_vars.CREDENTIALS]
  File "/home/airflow/.local/lib/python3.7/site-packages/google/auth/_default.py", line 111, in load_credentials_from_file
    with io.open(filename, "r") as file_obj:
IsADirectoryError: [Errno 21] Is a directory: '/.google/credentials/google_credentials.json'
[2022-11-27 03:53:37,836] {taskinstance.py:1277} INFO - Marking task as FAILED. dag_id=data_ingestation_gcp_dag, task_id=local_to_gcp_task, execution_date=20190102T060000, start_date=20221127T035337, end_date=20221127T035337
[2022-11-27 03:53:37,887] {standard_task_runner.py:92} ERROR - Failed to execute job 121 for task local_to_gcp_task
Traceback (most recent call last):
  File "/home/airflow/.local/lib/python3.7/site-packages/airflow/task/task_runner/standard_task_runner.py", line 85, in _start_by_fork
    args.func(args, dag=self.dag)
  File "/home/airflow/.local/lib/python3.7/site-packages/airflow/cli/cli_parser.py", line 48, in command
    return func(*args, **kwargs)
  File "/home/airflow/.local/lib/python3.7/site-packages/airflow/utils/cli.py", line 92, in wrapper
    return f(*args, **kwargs)
  File "/home/airflow/.local/lib/python3.7/site-packages/airflow/cli/commands/task_command.py", line 298, in task_run
    _run_task_by_selected_method(args, dag, ti)
  File "/home/airflow/.local/lib/python3.7/site-packages/airflow/cli/commands/task_command.py", line 107, in _run_task_by_selected_method
    _run_raw_task(args, ti)
  File "/home/airflow/.local/lib/python3.7/site-packages/airflow/cli/commands/task_command.py", line 184, in _run_raw_task
    error_file=args.error_file,
  File "/home/airflow/.local/lib/python3.7/site-packages/airflow/utils/session.py", line 70, in wrapper
    return func(*args, session=session, **kwargs)
  File "/home/airflow/.local/lib/python3.7/site-packages/airflow/models/taskinstance.py", line 1329, in _run_raw_task
    self._execute_task_with_callbacks(context)
  File "/home/airflow/.local/lib/python3.7/site-packages/airflow/models/taskinstance.py", line 1455, in _execute_task_with_callbacks
    result = self._execute_task(context, self.task)
  File "/home/airflow/.local/lib/python3.7/site-packages/airflow/models/taskinstance.py", line 1511, in _execute_task
    result = execute_callable(context=context)
  File "/home/airflow/.local/lib/python3.7/site-packages/airflow/operators/python.py", line 174, in execute
    return_value = self.execute_callable()
  File "/home/airflow/.local/lib/python3.7/site-packages/airflow/operators/python.py", line 185, in execute_callable
    return self.python_callable(*self.op_args, **self.op_kwargs)
  File "/opt/airflow/dags/data_ingestation_gcp.py", line 39, in upload_to_gcs
    client = storage.Client()
  File "/home/airflow/.local/lib/python3.7/site-packages/google/cloud/storage/client.py", line 128, in __init__
    _http=_http,
  File "/home/airflow/.local/lib/python3.7/site-packages/google/cloud/client.py", line 318, in __init__
    _ClientProjectMixin.__init__(self, project=project, credentials=credentials)
  File "/home/airflow/.local/lib/python3.7/site-packages/google/cloud/client.py", line 266, in __init__
    project = self._determine_default(project)
  File "/home/airflow/.local/lib/python3.7/site-packages/google/cloud/client.py", line 285, in _determine_default
    return _determine_default_project(project)
  File "/home/airflow/.local/lib/python3.7/site-packages/google/cloud/_helpers.py", line 186, in _determine_default_project
    _, project = google.auth.default()
  File "/home/airflow/.local/lib/python3.7/site-packages/google/auth/_default.py", line 459, in default
    credentials, project_id = checker()
  File "/home/airflow/.local/lib/python3.7/site-packages/google/auth/_default.py", line 222, in _get_explicit_environ_credentials
    os.environ[environment_vars.CREDENTIALS]
  File "/home/airflow/.local/lib/python3.7/site-packages/google/auth/_default.py", line 111, in load_credentials_from_file
    with io.open(filename, "r") as file_obj:
IsADirectoryError: [Errno 21] Is a directory: '/.google/credentials/google_credentials.json'
[2022-11-27 03:53:37,933] {local_task_job.py:154} INFO - Task exited with return code 1
[2022-11-27 03:53:38,185] {local_task_job.py:264} INFO - 0 downstream tasks scheduled from follow-on schedule check
