[2022-11-26 07:28:33,474] {taskinstance.py:1032} INFO - Dependencies all met for <TaskInstance: LocalIngestationDag_new.ingestation scheduled__2021-01-02T06:00:00+00:00 [queued]>
[2022-11-26 07:28:33,517] {taskinstance.py:1032} INFO - Dependencies all met for <TaskInstance: LocalIngestationDag_new.ingestation scheduled__2021-01-02T06:00:00+00:00 [queued]>
[2022-11-26 07:28:33,518] {taskinstance.py:1238} INFO - 
--------------------------------------------------------------------------------
[2022-11-26 07:28:33,519] {taskinstance.py:1239} INFO - Starting attempt 4 of 4
[2022-11-26 07:28:33,520] {taskinstance.py:1240} INFO - 
--------------------------------------------------------------------------------
[2022-11-26 07:28:33,564] {taskinstance.py:1259} INFO - Executing <Task(PythonOperator): ingestation> on 2021-01-02 06:00:00+00:00
[2022-11-26 07:28:33,575] {standard_task_runner.py:52} INFO - Started process 2630 to run task
[2022-11-26 07:28:33,584] {standard_task_runner.py:76} INFO - Running: ['***', 'tasks', 'run', 'LocalIngestationDag_new', 'ingestation', 'scheduled__2021-01-02T06:00:00+00:00', '--job-id', '96', '--raw', '--subdir', 'DAGS_FOLDER/data_ingestation.py', '--cfg-path', '/tmp/tmpxb972e0n', '--error-file', '/tmp/tmpgzs9jccz']
[2022-11-26 07:28:33,587] {standard_task_runner.py:77} INFO - Job 96: Subtask ingestation
[2022-11-26 07:28:33,731] {logging_mixin.py:109} INFO - Running <TaskInstance: LocalIngestationDag_new.ingestation scheduled__2021-01-02T06:00:00+00:00 [running]> on host 951f10ff76c7
[2022-11-26 07:28:33,901] {logging_mixin.py:109} WARNING - /home/***/.local/lib/python3.7/site-packages/***/utils/context.py:152 AirflowContextDeprecationWarning: Accessing 'execution_date' from the template is deprecated and will be removed in a future version. Please use 'data_interval_start' or 'logical_date' instead.
[2022-11-26 07:28:33,950] {taskinstance.py:1426} INFO - Exporting the following env vars:
AIRFLOW_CTX_DAG_OWNER=***
AIRFLOW_CTX_DAG_ID=LocalIngestationDag_new
AIRFLOW_CTX_TASK_ID=ingestation
AIRFLOW_CTX_EXECUTION_DATE=2021-01-02T06:00:00+00:00
AIRFLOW_CTX_DAG_RUN_ID=scheduled__2021-01-02T06:00:00+00:00
[2022-11-26 07:28:33,953] {logging_mixin.py:109} INFO - yellow_taxi_2021_01 /opt/***/output_2021-01.parquet 2021-01-02T06:00:00+00:00
[2022-11-26 07:28:33,954] {logging_mixin.py:109} INFO - 3.7.12
[2022-11-26 07:28:33,957] {logging_mixin.py:109} INFO - connection established successfully, inserting data...
[2022-11-26 07:28:34,039] {taskinstance.py:1700} ERROR - Task failed with exception
Traceback (most recent call last):
  File "/home/airflow/.local/lib/python3.7/site-packages/airflow/models/taskinstance.py", line 1329, in _run_raw_task
    self._execute_task_with_callbacks(context)
  File "/home/airflow/.local/lib/python3.7/site-packages/airflow/models/taskinstance.py", line 1455, in _execute_task_with_callbacks
    result = self._execute_task(context, self.task)
  File "/home/airflow/.local/lib/python3.7/site-packages/airflow/models/taskinstance.py", line 1511, in _execute_task
    result = execute_callable(context=context)
  File "/home/airflow/.local/lib/python3.7/site-packages/airflow/operators/python.py", line 174, in execute
    return_value = self.execute_callable()
  File "/home/airflow/.local/lib/python3.7/site-packages/airflow/operators/python.py", line 185, in execute_callable
    return self.python_callable(*self.op_args, **self.op_kwargs)
  File "/opt/airflow/dags/ingest_script.py", line 16, in ingest_callable
    df = pd.read_parquet(file)
  File "/home/airflow/.local/lib/python3.7/site-packages/pandas/io/parquet.py", line 500, in read_parquet
    **kwargs,
  File "/home/airflow/.local/lib/python3.7/site-packages/pandas/io/parquet.py", line 240, in read
    path_or_handle, columns=columns, **kwargs
  File "/home/airflow/.local/lib/python3.7/site-packages/pyarrow/parquet.py", line 1869, in read_table
    coerce_int96_timestamp_unit=coerce_int96_timestamp_unit
  File "/home/airflow/.local/lib/python3.7/site-packages/pyarrow/parquet.py", line 1679, in __init__
    [fragment], schema=fragment.physical_schema,
  File "pyarrow/_dataset.pyx", line 952, in pyarrow._dataset.Fragment.physical_schema.__get__
  File "pyarrow/error.pxi", line 143, in pyarrow.lib.pyarrow_internal_check_status
  File "pyarrow/error.pxi", line 99, in pyarrow.lib.check_status
pyarrow.lib.ArrowInvalid: Could not open Parquet input source '<Buffer>': Parquet magic bytes not found in footer. Either the file is corrupted or this is not a parquet file.
[2022-11-26 07:28:34,089] {taskinstance.py:1277} INFO - Marking task as FAILED. dag_id=LocalIngestationDag_new, task_id=ingestation, execution_date=20210102T060000, start_date=20221126T072833, end_date=20221126T072834
[2022-11-26 07:28:34,139] {standard_task_runner.py:92} ERROR - Failed to execute job 96 for task ingestation
Traceback (most recent call last):
  File "/home/airflow/.local/lib/python3.7/site-packages/airflow/task/task_runner/standard_task_runner.py", line 85, in _start_by_fork
    args.func(args, dag=self.dag)
  File "/home/airflow/.local/lib/python3.7/site-packages/airflow/cli/cli_parser.py", line 48, in command
    return func(*args, **kwargs)
  File "/home/airflow/.local/lib/python3.7/site-packages/airflow/utils/cli.py", line 92, in wrapper
    return f(*args, **kwargs)
  File "/home/airflow/.local/lib/python3.7/site-packages/airflow/cli/commands/task_command.py", line 298, in task_run
    _run_task_by_selected_method(args, dag, ti)
  File "/home/airflow/.local/lib/python3.7/site-packages/airflow/cli/commands/task_command.py", line 107, in _run_task_by_selected_method
    _run_raw_task(args, ti)
  File "/home/airflow/.local/lib/python3.7/site-packages/airflow/cli/commands/task_command.py", line 184, in _run_raw_task
    error_file=args.error_file,
  File "/home/airflow/.local/lib/python3.7/site-packages/airflow/utils/session.py", line 70, in wrapper
    return func(*args, session=session, **kwargs)
  File "/home/airflow/.local/lib/python3.7/site-packages/airflow/models/taskinstance.py", line 1329, in _run_raw_task
    self._execute_task_with_callbacks(context)
  File "/home/airflow/.local/lib/python3.7/site-packages/airflow/models/taskinstance.py", line 1455, in _execute_task_with_callbacks
    result = self._execute_task(context, self.task)
  File "/home/airflow/.local/lib/python3.7/site-packages/airflow/models/taskinstance.py", line 1511, in _execute_task
    result = execute_callable(context=context)
  File "/home/airflow/.local/lib/python3.7/site-packages/airflow/operators/python.py", line 174, in execute
    return_value = self.execute_callable()
  File "/home/airflow/.local/lib/python3.7/site-packages/airflow/operators/python.py", line 185, in execute_callable
    return self.python_callable(*self.op_args, **self.op_kwargs)
  File "/opt/airflow/dags/ingest_script.py", line 16, in ingest_callable
    df = pd.read_parquet(file)
  File "/home/airflow/.local/lib/python3.7/site-packages/pandas/io/parquet.py", line 500, in read_parquet
    **kwargs,
  File "/home/airflow/.local/lib/python3.7/site-packages/pandas/io/parquet.py", line 240, in read
    path_or_handle, columns=columns, **kwargs
  File "/home/airflow/.local/lib/python3.7/site-packages/pyarrow/parquet.py", line 1869, in read_table
    coerce_int96_timestamp_unit=coerce_int96_timestamp_unit
  File "/home/airflow/.local/lib/python3.7/site-packages/pyarrow/parquet.py", line 1679, in __init__
    [fragment], schema=fragment.physical_schema,
  File "pyarrow/_dataset.pyx", line 952, in pyarrow._dataset.Fragment.physical_schema.__get__
  File "pyarrow/error.pxi", line 143, in pyarrow.lib.pyarrow_internal_check_status
  File "pyarrow/error.pxi", line 99, in pyarrow.lib.check_status
pyarrow.lib.ArrowInvalid: Could not open Parquet input source '<Buffer>': Parquet magic bytes not found in footer. Either the file is corrupted or this is not a parquet file.
[2022-11-26 07:28:34,165] {local_task_job.py:154} INFO - Task exited with return code 1
[2022-11-26 07:28:34,256] {local_task_job.py:264} INFO - 0 downstream tasks scheduled from follow-on schedule check
